Workbook

Sheet Read Me
A1: CRADI / EWER app — translation review
A3: What this is
A4: Every piece of text in the EWER mobile app, with its English source and the AI-generated translation for each language. Please review and correct the translations for your language.
A6: How to review
A7: 1. Open the tab for your language.
A8: 2. Read "English" and "Where it appears", then check "Translation".
A9: 3. If it is wrong or unnatural, type the corrected text in the yellow "Your correction" column. Leave it empty if the translation is fine.
A10: 4. Set "Status" (yellow) to OK, Corrected or Unsure. Add any comment in "Notes" (yellow).
A11: 5. Rows marked "Please check" in the "AI flag" column are ones the translator was least sure about — start with those.
A13: Important rules for corrections
A14: • Keep anything in curly braces exactly as it is, e.g. {name}, {count}. They are replaced by real values in the app.
A15: • For rows containing "plural" or "select", only change the words inside the inner braces; keep the keywords (plural, select, other, one, =1) unchanged.
... A20: Only edit the yellow columns. The Summary tab counts progress automatically.

Sheet Summary
A1: Language | B1: Strings | C1: AI-flagged "Please check" | D1: "May be too long" | E1: Reviewed (Status set) | F1: Marked Corrected | G1: Marked Unsure | H1: % reviewed
A2: Hausa | B2: =COUNTA('Hausa'!A2:A957) | C2: =COUNTIF('Hausa'!E2:E957,"Please check") | D2: =COUNTIF('Hausa'!E2:E957,"May be too long") | E2: =COUNTA('Hausa'!G2:G957) | F2: =COUNTIF('Hausa'!G2:G957,"Corrected") | G2: =COUNTIF('Hausa'!G2:G957,"Unsure") | H2: =IFERROR(E2/B2,0)
A3: Yoruba | B3: =COUNTA('Yoruba'!A2:A957) | C3: =COUNTIF('Yoruba'!E2:E957,"Please check") | D3: =COUNTIF('Yoruba'!E2:E957,"May be too long") | E3: =COUNTA('Yoruba'!G2:G957) | F3: =COUNTIF('Yoruba'!G2:G957,"Corrected") | G3: =COUNTIF('Yoruba'!G2:G957,"Unsure") | H3: =IFERROR(E3/B3,0)
A4: Igbo | B4: =COUNTA('Igbo'!A2:A957) | C4: =COUNTIF('Igbo'!E2:E957,"Please check") | D4: =COUNTIF('Igbo'!E2:E957,"May be too long") | E4: =COUNTA('Igbo'!G2:G957) | F4: =COUNTIF('Igbo'!G2:G957,"Corrected") | G4: =COUNTIF('Igbo'!G2:G957,"Unsure") | H4: =IFERROR(E4/B4,0)
A5: Nigerian Pidgin | B5: =COUNTA('Nigerian Pidgin'!A2:A957) | C5: =COUNTIF('Nigerian Pidgin'!E2:E957,"Please check") | D5: =COUNTIF('Nigerian Pidgin'!E2:E957,"May be too long") | E5: =COUNTA('Nigerian Pidgin'!G2:G957) | F5: =COUNTIF('Nigerian Pidgin'!G2:G957,"Corrected") | G5: =COUNTIF('Nigerian Pidgin'!G2:G957,"Unsure") | H5: =IFERROR(E5/B5,0)
A7: Counts update automatically from each language tab.

Sheet Hausa
A1: Key | B1: Where it appears | C1: English | D1: Translation | E1: AI flag | F1: Your correction | G1: Status | H1: Notes
A2: appTitle | B2: The application title. Used in: main. | C2: EWER Early Warning | D2: EWER Gargaɗin Farko
A3: monitoringZone | B3: Label for monitoring zone header. Used in: home screen. | C3: Monitoring Zone | D3: Yankin Sa Ido
A4: toVerify | B4: Tab label for reports pending verification. Used in: home screen. | C4: To Verify | D4: Don Tabbatarwa
A5: alerts | B5: Tab label for alerts. Used in: alerts list screen, home screen. | C5: Alerts | D5: Faɗakarwa
A6: myReports | B6: Tab label for user's own reports. Used in: home screen, my reports screen, user profile screen. | C6: My Reports | D6: Rahotannina
A7: browseCategories | B7: Section header for hazard categories. Used in: home screen, knowledge base screen. | C7: Browse Categories | D7: Duba Nau'o'i
A8: noReportsToVerify | B8: Empty state for verification tab. Used in: home screen. | C8: No reports to verify | D8: Babu rahotanni don tabbatarwa
A9: noActiveAlerts | B9: Empty state for alerts tab. Used in: admin alerts screen, alerts list screen. | C9: No active alerts | D9: Babu faɗakarwa a yanzu
A10: seeAll | B10: Link to view all items in a section. Used in: home screen, knowledge base screen. | C10: See All | D10: Duba Duka
A11: notifications | B11: Upper-case caption on the settings screen. | C11: NOTIFICATIONS | D11: SANARWA
A12: pushNotifications | B12: UI text on the settings screen. | C12: Push Notifications | D12: Sanarwa Kai Tsaye | E12: Please check
A13: general | B13: Upper-case caption on the settings screen. | C13: GENERAL | D13: GABAƊAYA
A14: language | B14: UI text on the settings screen. | C14: Language | D14: Harshe
A15: helpFaq | B15: UI text on the settings screen. | C15: Help & FAQ | D15: Taimako da Tambayoyi | E15: May be too long
A16: aboutApp | B16: UI text on the about app screen, settings screen. | C16: About App | D16: Game da App
A17: logout | B17: Button label (keep short, max ~20 chars) on the access code verification screen, main shell screen, pending approval screen. | C17: Log Out | D17: Fita
A18: back | B18: Button label (keep short, max ~20 chars) on the settings screen. | C18: Back | D18: Komawa
A19: cancel | B19: Button label (keep short, max ~20 chars) on the admin knowledge screen, admin reports screen, admin users screen. | C19: Cancel | D19: Soke
A20: save | B20: Button label (keep short, max ~20 chars) on the emergency contacts screen, user profile screen. | C20: Save | D20: Ajiye
A21: delete | B21: Button label (keep short, max ~20 chars) on the admin knowledge screen, emergency contacts screen, notifications screen. | C21: Delete | D21: Goge
A22: edit | B22: Button label (keep short, max ~20 chars) on the emergency contacts screen. | C22: Edit | D22: Gyara
A23: continueButton | B23: Button label (keep short, max ~20 chars) on the hazard selection screen, permission service. | C23: Continue | D23: Ci gaba
A24: retry | B24: Button label (keep short, max ~20 chars) on the admin reports screen, admin screen, admin users screen. | C24: Retry | D24: Sake Gwadawa | E24: May be too long
A25: close | B25: Button label (keep short, max ~20 chars) on the about app screen, sos sheet. | C25: Close | D25: Rufe
A26: settingsTitle | B26: Settings screen title. Used in: settings screen. | C26: Settings | D26: Saituna
A27: verifyPhoneNumber | B27: UI text on the otp verification screen. | C27: Verify Phone Number | D27: Tabbatar da Lambar Waya
A28: resendCode | B28: Button label (keep short, max ~20 chars) on the access code verification screen, otp verification screen. | C28: Resend Code | D28: Sake Aika Lambar
A29: verify | B29: Button label (keep short, max ~20 chars) on the user profile screen. | C29: Verify | D29: Tabbatar
A30: selectHazard | B30: UI text on the hazard selection screen. | C30: Select Hazard | D30: Zaɓi Haɗari
A31: whatIncident | B31: UI text on the hazard selection screen. | C31: What type of incident are you reporting? | D31: Wane irin lamari kake bayar da rahoto?
A32: erosion | B32: UI text on the home screen. | C32: Erosion | D32: Zaizaya
A33: howSevereSituation | B33: UI text on the severity selection screen. | C33: How severe is the situation? | D33: Yaya tsananin lamarin?
A34: setSeverity | B34: UI text on the severity selection screen. | C34: Set Severity | D34: Zaɓi Tsanani
A35: nextLocation | B35: UI text on the severity selection screen. | C35: Next: Location | D35: Na Gaba: Wuri
A36: lowMinorImpact | B36: UI text on the severity selection screen. | C36: Low - Minor impact | D36: Ƙarami - Tasiri kaɗan
... A49: languagePreference | B49: UI text on the user profile screen. | C49: Language Preference | D49: Zaɓin Harshe
A50: offlineDataSync | B50: UI text on the user profile screen. | C50: Offline Data Sync | D50: Daidaita Bayanan da Aka Ajiye | E50: May be too long
A51: upToDate | B51: UI text on the user profile screen. | C51: Up to date | D51: An sabunta
A52: helpSupport | B52: UI text on the help support screen, user profile screen. | C52: Help & Support | D52: Taimako da Goyon Baya
...

Sheet Yoruba
A1: Key | B1: Where it appears | C1: English | D1: Translation | E1: AI flag | F1: Your correction | G1: Status | H1: Notes
A2: appTitle | B2: The application title. Used in: main. | C2: EWER Early Warning | D2: EWER Ìkìlọ̀ Kùtùkùtù
A3: monitoringZone | B3: Label for monitoring zone header. Used in: home screen. | C3: Monitoring Zone | D3: Agbègbè Àbójútó
A4: toVerify | B4: Tab label for reports pending verification. Used in: home screen. | C4: To Verify | D4: Láti Jẹ́rìísí
A5: alerts | B5: Tab label for alerts. Used in: alerts list screen, home screen. | C5: Alerts | D5: Àwọn Ìkìlọ̀
A6: myReports | B6: Tab label for user's own reports. Used in: home screen, my reports screen, user profile screen. | C6: My Reports | D6: Àwọn Ìròyìn Mi
A7: browseCategories | B7: Section header for hazard categories. Used in: home screen, knowledge base screen. | C7: Browse Categories | D7: Wo Àwọn Ẹ̀ka
A8: noReportsToVerify | B8: Empty state for verification tab. Used in: home screen. | C8: No reports to verify | D8: Kò sí ìròyìn láti jẹ́rìísí
A9: noActiveAlerts | B9: Empty state for alerts tab. Used in: admin alerts screen, alerts list screen. | C9: No active alerts | D9: Kò sí ìkìlọ̀ tó ń lọ lọ́wọ́ | E9: May be too long
A10: seeAll | B10: Link to view all items in a section. Used in: home screen, knowledge base screen. | C10: See All | D10: Wo Gbogbo Rẹ̀
A11: notifications | B11: Upper-case caption on the settings screen. | C11: NOTIFICATIONS | D11: ÌFITÓNILÉTÍ
A12: pushNotifications | B12: UI text on the settings screen. | C12: Push Notifications | D12: Ìfitónilétí Orí Fóònù
A13: general | B13: Upper-case caption on the settings screen. | C13: GENERAL | D13: GBOGBOGBÒ
A14: language | B14: UI text on the settings screen. | C14: Language | D14: Èdè
A15: helpFaq | B15: UI text on the settings screen. | C15: Help & FAQ | D15: Ìrànlọ́wọ́ & Ìbéèrè | E15: May be too long
A16: aboutApp | B16: UI text on the about app screen, settings screen. | C16: About App | D16: Nípa Áàpù | E16: Please check
A17: logout | B17: Button label (keep short, max ~20 chars) on the access code verification screen, main shell screen, pending approval screen. | C17: Log Out | D17: Jáde
A18: back | B18: Button label (keep short, max ~20 chars) on the settings screen. | C18: Back | D18: Padà
A19: cancel | B19: Button label (keep short, max ~20 chars) on the admin knowledge screen, admin reports screen, admin users screen. | C19: Cancel | D19: Fagilé
A20: save | B20: Button label (keep short, max ~20 chars) on the emergency contacts screen, user profile screen. | C20: Save | D20: Fi Pamọ́
A21: delete | B21: Button label (keep short, max ~20 chars) on the admin knowledge screen, emergency contacts screen, notifications screen. | C21: Delete | D21: Pa Rẹ́
A22: edit | B22: Button label (keep short, max ~20 chars) on the emergency contacts screen. | C22: Edit | D22: Ṣàtúnṣe
A23: continueButton | B23: Button label (keep short, max ~20 chars) on the hazard selection screen, permission service. | C23: Continue | D23: Tẹ̀síwájú
A24: retry | B24: Button label (keep short, max ~20 chars) on the admin reports screen, admin screen, admin users screen. | C24: Retry | D24: Tún Gbìyànjú | E24: May be too long
A25: close | B25: Button label (keep short, max ~20 chars) on the about app screen, sos sheet. | C25: Close | D25: Pa Dé
A26: settingsTitle | B26: Settings screen title. Used in: settings screen. | C26: Settings | D26: Ètò
A27: verifyPhoneNumber | B27: UI text on the otp verification screen. | C27: Verify Phone Number | D27: Jẹ́rìísí Nọ́mbà Fóònù
A28: resendCode | B28: Button label (keep short, max ~20 chars) on the access code verification screen, otp verification screen. | C28: Resend Code | D28: Tún Kóòdù Fi Ránṣẹ́ | E28: May be too long
A29: verify | B29: Button label (keep short, max ~20 chars) on the user profile screen. | C29: Verify | D29: Jẹ́rìísí
A30: selectHazard | B30: UI text on the hazard selection screen. | C30: Select Hazard | D30: Yan Ewu
A31: whatIncident | B31: UI text on the hazard selection screen. | C31: What type of incident are you reporting? | D31: Irú ìṣẹ̀lẹ̀ wo lò ń ròyìn rẹ̀?
A32: erosion | B32: UI text on the home screen. | C32: Erosion | D32: Ìjẹ̀bàjẹ́ Ilẹ̀ | E32: Please check
A33: howSevereSituation | B33: UI text on the severity selection screen. | C33: How severe is the situation? | D33: Báwo ni ipò náà ṣe le tó?
A34: setSeverity | B34: UI text on the severity selection screen. | C34: Set Severity | D34: Ṣètò Bí Ó Ti Le Tó
A35: nextLocation | B35: UI text on the severity selection screen. | C35: Next: Location | D35: Èyí tó kàn: Ibi
A36: lowMinorImpact | B36: UI text on the severity selection screen. | C36: Low - Minor impact | D36: Kéré - Ipa díẹ̀
A37: mediumNoticeableImpact | B37: UI text on the severity selection screen. | C37: Medium - Noticeable impact | D37: Àárín - Ipa tó hàn gbangba
A38: highSignificantDamage | B38: UI text on the severity selection screen. | C38: High - Significant damage | D38: Ga - Ìbàjẹ́ ńlá
A39: criticalLifeThreatening | B39: UI text on the severity selection screen. | C39: Critical - Life threatening | D39: Ewu Ńlá - Ó léwu fún ẹ̀mí
A40: camera | B40: UI text on the user profile screen. | C40: Camera | D40: Kámẹ́rà
...

Sheet Igbo
A1: Key | B1: Where it appears | C1: English | D1: Translation | E1: AI flag | F1: Your correction | G1: Status | H1: Notes
A2: appTitle | B2: The application title. Used in: main. | C2: EWER Early Warning | D2: EWER Ịdọ Aka ná Ntị n'Oge
A3: monitoringZone | B3: Label for monitoring zone header. Used in: home screen. | C3: Monitoring Zone | D3: Mpaghara Nlekọta
A4: toVerify | B4: Tab label for reports pending verification. Used in: home screen. | C4: To Verify | D4: Ịnyocha
A5: alerts | B5: Tab label for alerts. Used in: alerts list screen, home screen. | C5: Alerts | D5: Ọkwa | E5: Please check
A6: myReports | B6: Tab label for user's own reports. Used in: home screen, my reports screen, user profile screen. | C6: My Reports | D6: Akụkọ M
A7: browseCategories | B7: Section header for hazard categories. Used in: home screen, knowledge base screen. | C7: Browse Categories | D7: Lelee Ụdị Dị Iche Iche
A8: noReportsToVerify | B8: Empty state for verification tab. Used in: home screen. | C8: No reports to verify | D8: Enweghị akụkọ a ga-enyocha
A9: noActiveAlerts | B9: Empty state for alerts tab. Used in: admin alerts screen, alerts list screen. | C9: No active alerts | D9: Enweghị ọkwa na-arụ ọrụ
A10: seeAll | B10: Link to view all items in a section. Used in: home screen, knowledge base screen. | C10: See All | D10: Hụ Ha Niile
A11: notifications | B11: Upper-case caption on the settings screen. | C11: NOTIFICATIONS | D11: ỌKWA | E11: Please check
A12: pushNotifications | B12: UI text on the settings screen. | C12: Push Notifications | D12: Ọkwa Mbanye
A13: general | B13: Upper-case caption on the settings screen. | C13: GENERAL | D13: IZUGBE
A14: language | B14: UI text on the settings screen. | C14: Language | D14: Asụsụ
A15: helpFaq | B15: UI text on the settings screen. | C15: Help & FAQ | D15: Enyemaka & Ajụjụ
A16: aboutApp | B16: UI text on the about app screen, settings screen. | C16: About App | D16: Maka Ngwa A
A17: logout | B17: Button label (keep short, max ~20 chars) on the access code verification screen, main shell screen, pending approval screen. | C17: Log Out | D17: Pụọ
A18: back | B18: Button label (keep short, max ~20 chars) on the settings screen. | C18: Back | D18: Laghachi
A19: cancel | B19: Button label (keep short, max ~20 chars) on the admin knowledge screen, admin reports screen, admin users screen. | C19: Cancel | D19: Kagbuo
A20: save | B20: Button label (keep short, max ~20 chars) on the emergency contacts screen, user profile screen. | C20: Save | D20: Chekwaa
A21: delete | B21: Button label (keep short, max ~20 chars) on the admin knowledge screen, emergency contacts screen, notifications screen. | C21: Delete | D21: Hichapụ
A22: edit | B22: Button label (keep short, max ~20 chars) on the emergency contacts screen. | C22: Edit | D22: Dezie
A23: continueButton | B23: Button label (keep short, max ~20 chars) on the hazard selection screen, permission service. | C23: Continue | D23: Gaa n'ihu
... A31: whatIncident | B31: UI text on the hazard selection screen. | C31: What type of incident are you reporting? | D31: Kedu ụdị ihe mere ị na-akọ?
A32: erosion | B32: UI text on the home screen. | C32: Erosion | D32: Mbuze Ala | E32: Please check
A33: howSevereSituation | B33: UI text on the severity selection screen. | C33: How severe is the situation? | D33: Olee otú ọnọdụ ahụ si njọ?
A34: setSeverity | B34: UI text on the severity selection screen. | C34: Set Severity | D34: Tọọ Ogo Njọ
A35: nextLocation | B35: UI text on the severity selection screen. | C35: Next: Location | D35: Ọzọ: Ebe
A36: lowMinorImpact | B36: UI text on the severity selection screen. | C36: Low - Minor impact | D36: Obere - Mmetụta nta
A37: mediumNoticeableImpact | B37: UI text on the severity selection screen. | C37: Medium - Noticeable impact | D37: Etiti - Mmetụta a na-ahụ anya
A38: highSignificantDamage | B38: UI text on the severity selection screen. | C38: High - Significant damage | D38: Elu - Oke mmebi
A39: criticalLifeThreatening | B39: UI text on the severity selection screen. | C39: Critical - Life threatening | D39: Oke Egwu - Na-etinye ndụ n'ihe egwu
A40: camera | B40: UI text on the user profile screen. | C40: Camera | D40: Kamera
A41: useMyLocationInfo | B41: UI text on the location picker screen. | C41: Use My Location Info | D41: Jiri Ozi Ebe M Nọ
A42: myProfile | B42: UI text on the user profile screen. | C42: My Profile | D42: Profaịlụ M
A43: editProfileDetails | B43: UI text on the user profile screen. | C43: Edit Profile Details | D43: Dezie Nkọwa Profaịlụ
A44: fullName | B44: UI text on the registration screen, user profile screen. | C44: Full Name | D44: Aha Zuru Ezu
... A49: languagePreference | B49: UI text on the user profile screen. | C49: Language Preference | D49: Asụsụ Ị Họọrọ
A50: offlineDataSync | B50: UI text on the user profile screen. | C50: Offline Data Sync | D50: Mmekọrịta Data Na-enweghị Ịntanetị | E50: Please check
A51: upToDate | B51: UI text on the user profile screen. | C51: Up to date | D51: Ọ dị ọhụrụ
...

Sheet Nigerian Pidgin
A1: Key | B1: Where it appears | C1: English | D1: Translation | E1: AI flag | F1: Your correction | G1: Status | H1: Notes
A2: appTitle | B2: The application title. Used in: main. | C2: EWER Early Warning | D2: EWER Early Warning
A3: monitoringZone | B3: Label for monitoring zone header. Used in: home screen. | C3: Monitoring Zone | D3: Area Wey We Dey Watch
A4: toVerify | B4: Tab label for reports pending verification. Used in: home screen. | C4: To Verify | D4: To Confam
A5: alerts | B5: Tab label for alerts. Used in: alerts list screen, home screen. | C5: Alerts | D5: Alerts
A6: myReports | B6: Tab label for user's own reports. Used in: home screen, my reports screen, user profile screen. | C6: My Reports | D6: My Reports
A7: browseCategories | B7: Section header for hazard categories. Used in: home screen, knowledge base screen. | C7: Browse Categories | D7: Check Categories
A8: noReportsToVerify | B8: Empty state for verification tab. Used in: home screen. | C8: No reports to verify | D8: No report dey to confam
A9: noActiveAlerts | B9: Empty state for alerts tab. Used in: admin alerts screen, alerts list screen. | C9: No active alerts | D9: No alert dey now
A10: seeAll | B10: Link to view all items in a section. Used in: home screen, knowledge base screen. | C10: See All | D10: See Everything | E10: May be too long
A11: notifications | B11: Upper-case caption on the settings screen. | C11: NOTIFICATIONS | D11: NOTIFICATIONS
A12: pushNotifications | B12: UI text on the settings screen. | C12: Push Notifications | D12: Push Notifications
A13: general | B13: Upper-case caption on the settings screen. | C13: GENERAL | D13: GENERAL
A14: language | B14: UI text on the settings screen. | C14: Language | D14: Language
A15: helpFaq | B15: UI text on the settings screen. | C15: Help & FAQ | D15: Help & Questions
A16: aboutApp | B16: UI text on the about app screen, settings screen. | C16: About App | D16: About Di App
A17: logout | B17: Button label (keep short, max ~20 chars) on the access code verification screen, main shell screen, pending approval screen. | C17: Log Out | D17: Log Out | E17: Please check
A18: back | B18: Button label (keep short, max ~20 chars) on the settings screen. | C18: Back | D18: Go Back
A19: cancel | B19: Button label (keep short, max ~20 chars) on the admin knowledge screen, admin reports screen, admin users screen. | C19: Cancel | D19: Cancel
A20: save | B20: Button label (keep short, max ~20 chars) on the emergency contacts screen, user profile screen. | C20: Save | D20: Save
A21: delete | B21: Button label (keep short, max ~20 chars) on the admin knowledge screen, emergency contacts screen, notifications screen. | C21: Delete | D21: Delete
A22: edit | B22: Button label (keep short, max ~20 chars) on the emergency contacts screen. | C22: Edit | D22: Change
A23: continueButton | B23: Button label (keep short, max ~20 chars) on the hazard selection screen, permission service. | C23: Continue | D23: Continue
A24: retry | B24: Button label (keep short, max ~20 chars) on the admin reports screen, admin screen, admin users screen. | C24: Retry | D24: Try Again
A25: close | B25: Button label (keep short, max ~20 chars) on the about app screen, sos sheet. | C25: Close | D25: Close
A26: settingsTitle | B26: Settings screen title. Used in: settings screen. | C26: Settings | D26: Settings
A27: verifyPhoneNumber | B27: UI text on the otp verification screen. | C27: Verify Phone Number | D27: Confam Phone Number
A28: resendCode | B28: Button label (keep short, max ~20 chars) on the access code verification screen, otp verification screen. | C28: Resend Code | D28: Send Code Again
A29: verify | B29: Button label (keep short, max ~20 chars) on the user profile screen. | C29: Verify | D29: Confam
... A35: nextLocation | B35: UI text on the severity selection screen. | C35: Next: Location | D35: Next: Location
A36: lowMinorImpact | B36: UI text on the severity selection screen. | C36: Low - Minor impact | D36: Low - E no too bad | E36: Please check
A37: mediumNoticeableImpact | B37: UI text on the severity selection screen. | C37: Medium - Noticeable impact | D37: Medium - E dey show small
A38: highSignificantDamage | B38: UI text on the severity selection screen. | C38: High - Significant damage | D38: High - E don scatter plenty tins | E38: Please check
A39: criticalLifeThreatening | B39: UI text on the severity selection screen. | C39: Critical - Life threatening | D39: Critical - Life dey for danger
A40: camera | B40: UI text on the user profile screen. | C40: Camera | D40: Camera
A41: useMyLocationInfo | B41: UI text on the location picker screen. | C41: Use My Location Info | D41: Use My Location
A42: myProfile | B42: UI text on the user profile screen. | C42: My Profile | D42: My Profile
A43: editProfileDetails | B43: UI text on the user profile screen. | C43: Edit Profile Details | D43: Change Profile Details
A44: fullName | B44: UI text on the registration screen, user profile screen. | C44: Full Name | D44: Full Name
A45: emailAddress | B45: UI text on the forgot password screen, login screen, registration screen. | C45: Email Address | D45: Email Address
...
